## MagNavPy Error Analysis and Refactoring Plan

This report outlines the analysis of 7 persistent `pytest` errors in the `MagNavPy` project, identifies systemic issues, and proposes a holistic refactoring plan to address these errors.

### Systemic Issues and Patterns Identified

1.  **`.mat` File Data Handling:**
    *   **Inconsistent Unwrapping:** Data loaded using `scipy.io.loadmat` often requires careful unwrapping of nested structures (e.g., accessing `data['field'][0][0]`) to get to the actual NumPy array. This is inconsistently applied across test files.
    *   **Missing Type Conversion:** Loaded numerical data is not always explicitly converted to `float` (e.g., using `.astype(float)`), which can leave arrays with `dtype=object` or other inappropriate types, causing issues with NumPy ufuncs or other numerical operations.
    *   **Shape Mismatches:** Arrays loaded from `.mat` files (which might be 2D column/row vectors) are not always correctly reshaped/flattened to 1D arrays as expected by Python functions.

2.  **NumPy Array Mismanagement:**
    *   **Incorrect Slicing:** Several errors stem from incorrect array slicing, particularly when dealing with time series data or multi-component vectors (e.g., `array[:, 0]` used when `array[0, :]` was intended for the first sample's components).
    *   **DCM `Cnb` Shape Convention:** A critical issue is the shape of the Direction Cosine Matrix (`Cnb`). It appears to be created as `(N, 3, 3)` (N samples, 3x3 matrix) in some parts of the data generation pipeline (e.g., via placeholder `create_dcm_from_vel`), while consuming functions (like those building the Pinson matrix for EKF propagation) expect it as `(3, 3, N)` for time-stacked DCMs, or a single `(3,3)` matrix for a given time step `t` (correctly sliced as `Cnb_proper_shape[:,:,t]`). This mismatch leads to incorrect data being passed and subsequent `IndexError` or `ValueError`.

3.  **Python Porting Discrepancies from Julia:**
    *   **Function Signature Mismatches:** At least one error (Error 6) indicates a `TypeError` due to an unexpected keyword argument, suggesting a mismatch between the Python function definition and how it's called, possibly due to an older version of the function being active or an oversight in porting.
    *   **Logic/Type Check Issues:** Some ported logic, like the `isinstance` check in `ekf.py` (Error 3), does not align with the capabilities of the functions it calls (e.g., `get_h`/`get_H` can handle interpolators, but the check prematurely blocks them).

4.  **Impact of Placeholder Functions:**
    *   The use of placeholder functions (e.g., `create_dcm_from_vel`, NN model interaction functions) can mask underlying issues or introduce new ones if their output shapes/types do not precisely match what the consuming production code expects. The `Cnb` shape issue is a prime example.

5.  **Test Data Integrity and Usage:**
    *   Some tests might be using data in a way that doesn't fully align with the Python function's expectations, especially if the test logic was directly translated from Julia without accounting for Python/NumPy conventions (e.g., 0-based vs. 1-based indexing, slicing behavior).

---

### Detailed Error Analysis and Refactoring Plan

Below is the analysis and plan for each of the 7 persistent errors.

---

**1. Error: `ERROR tests/test_create_xyz.py - TypeError: loop of ufunc does not support argument 0 of type numpy.ndarray which has no callable sqrt method`**

*   **Persisting Reason:** The data loading for `flux_a_x_traj`, `flux_a_y_traj`, `flux_a_z_traj` from the `.mat` file likely remains uncorrected, leading to these arrays not being simple 1D float arrays.
*   **Root Cause Hypothesis:**
    *   The variables `flux_a_x_traj`, `flux_a_y_traj`, `flux_a_z_traj` are loaded from `traj_data_mat` in `tests/test_create_xyz.py` (lines 99-101) using only `.ravel()`.
    *   Unlike other variables (e.g., `lat_traj` on line 88), this extraction misses the common `[0][0]` indexing needed for `scipy.io.loadmat` when dealing with MATLAB structs/cells, and also lacks an explicit `.astype(float)` conversion.
    *   Consequently, these flux components likely remain as object arrays or nested arrays.
    *   The expression `flux_a_x_traj**2 + flux_a_y_traj**2 + flux_a_z_traj**2` (line 140) then results in an array that `np.sqrt` cannot process, as the ufunc expects numeric elements, not array-like objects without a `sqrt` method.
*   **Actionable Plan (for Code Mode):**
    1.  **Modify File:** `tests/test_create_xyz.py`
    2.  **Locate Lines:** 99, 100, 101.
    3.  **Change:** Update the extraction of `flux_a_x_traj`, `flux_a_y_traj`, and `flux_a_z_traj` to correctly unwrap the data from the `.mat` structure and ensure they are 1D float arrays.
        ```python
        # Current:
        # flux_a_x_traj = traj_data_mat["flux_a_x"].ravel()
        # flux_a_y_traj = traj_data_mat["flux_a_y"].ravel()
        # flux_a_z_traj = traj_data_mat["flux_a_z"].ravel()

        # Proposed Change (mirroring lat_traj extraction):
        flux_a_x_traj = traj_data_mat["flux_a_x"][0][0].ravel().astype(float)
        flux_a_y_traj = traj_data_mat["flux_a_y"][0][0].ravel().astype(float)
        flux_a_z_traj = traj_data_mat["flux_a_z"][0][0].ravel().astype(float)
        ```
    4.  **Verify:** Ensure that after this change, `flux_a_x_traj`, `flux_a_y_traj`, and `flux_a_z_traj` are 1D NumPy arrays with a numeric dtype (e.g., `float64`). This will allow the arithmetic operations and `np.sqrt` on line 140 to execute correctly.

---

**2. Error: `ERROR tests/test_dcm.py - ValueError: 1D tilt_err must have 3 elements.`**

*   **Persisting Reason:** The incorrect slicing of `tilt_err_jl` when calling `correct_Cnb` for a single DCM has not been addressed.
*   **Root Cause Hypothesis:**
    *   In `tests/test_dcm.py` (line 81), `correct_Cnb` is called as: `correct_Cnb(cnb_1_py, tilt_err_jl[:, 0])`.
    *   `cnb_1_py` is a single (3x3) DCM.
    *   `tilt_err_jl` is loaded from `dcm_data["tilt_err"]`. Assuming `tilt_err_jl` is an `(N, 3)` array (N samples, 3 tilt components), the slice `tilt_err_jl[:, 0]` extracts the *first component for all N samples*, resulting in a 1D array of shape `(N,)`.
    *   The `correct_Cnb` function in `dcm_util.py` (lines 333-336) validates that if `tilt_err` is 1D, it must have exactly 3 elements. Since `N` (number of samples) is likely not 3, this check fails.
    *   The intent for correcting a single DCM `cnb_1_py` is to use the tilt errors for the *first sample*, which would be `tilt_err_jl[0, :]` (yielding a 1D array of 3 elements).
*   **Actionable Plan (for Code Mode):**
    1.  **Modify File:** `tests/test_dcm.py`
    2.  **Locate Line:** 81.
    3.  **Change:** Modify the slicing of `tilt_err_jl` to select the first row (all 3 components for the first sample) instead of the first column.
        ```python
        # Current:
        # cnb_estimate_1_py = correct_Cnb(cnb_1_py, tilt_err_jl[:, 0])

        # Proposed Change:
        cnb_estimate_1_py = correct_Cnb(cnb_1_py, tilt_err_jl[0, :])
        ```
    4.  **Verify:** Ensure `tilt_err_jl[0, :]` produces a 1D NumPy array of shape `(3,)` before being passed to `correct_Cnb`.

---

**3. Error: `ERROR tests/test_ekf_crlb.py - TypeError: map_obj must be MapS or MapS3D.`**

*   **Persisting Reason:** The `isinstance` check within `ekf.py` (and potentially `crlb` if it has similar internal calls) incorrectly assumes that `get_h`/`get_H` always require a raw map object, failing when a valid callable interpolator (especially from `MapCache`) is passed.
*   **Root Cause Hypothesis:**
    *   The `ekf` function in `magnavpy/ekf.py` (lines 175-178 and 194-196) has an `isinstance(current_itp_mapS_for_step, (MapS, MapS3D))` check before calling `get_h` and `get_H`.
    *   The `itp_mapS` parameter of `ekf` is documented to accept a callable interpolator or a `MapCache`.
    *   If `itp_mapS` is a `MapCache`, the `ekf` function extracts an *interpolator function* (a `scipy.interpolate.RegularGridInterpolator` instance) from the cache and assigns it to `current_itp_mapS_for_step`.
    *   This interpolator function then fails the `isinstance(..., (MapS, MapS3D))` check, raising the `TypeError`.
    *   However, `get_h` and `get_H` (from `model_functions.py`) are designed to accept either a raw `MapS`/`MapS3D` object (from which they can create an interpolator) or a pre-existing callable interpolator.
    *   The `isinstance` check in `ekf.py` is therefore overly restrictive and incorrect for the `MapCache` case.
*   **Actionable Plan (for Code Mode):**
    1.  **Modify File:** `magnavpy/ekf.py`
    2.  **Locate Lines:** Approximately 175-178 (before `get_h`) and 194-196 (before `get_H`).
    3.  **Change:** Remove or modify the problematic `isinstance` checks. Since `get_h` and `get_H` can handle callable interpolators, the check is not needed if `current_itp_mapS_for_step` is a valid callable. If it's `None` (e.g., interpolator creation failed), `get_h`/`get_H` should handle that gracefully or error appropriately themselves.
        ```python
        # Current problematic check before get_h:
        # if not isinstance(current_itp_mapS_for_step, (MapS, MapS3D)):
        #     raise TypeError(f'map_obj for get_h must be MapS or MapS3D, but got {type(current_itp_mapS_for_step)}')
        # h_pred = get_h(current_itp_mapS_for_step, ...)

        # Proposed Change (remove the check, ensure get_h handles None if current_itp_mapS_for_step can be None):
        # Option 1: Remove check, rely on get_h/get_H's internal handling (preferred if they are robust)
        h_pred = get_h(current_itp_mapS_for_step, x, lat_t, lon_t, alt_t,
                       date=date, core=core, der_map=current_der_mapS_for_step, map_alt=map_alt)

        # Similarly for the check before get_H:
        # Current problematic check before get_H:
        # if not isinstance(current_itp_mapS_for_step, (MapS, MapS3D)):
        #     raise TypeError(f'map_obj for get_H must be MapS or MapS3D, but got {type(current_itp_mapS_for_step)}')
        # H_m = get_H(current_itp_mapS_for_step, ...)

        # Proposed Change:
        H_m = get_H(current_itp_mapS_for_step, x, lat_t, lon_t, alt_t,
                    date=date, core=core)
        ```
    4.  **Verify:** Ensure `get_h` and `get_H` in `model_functions.py` correctly handle cases where their `itp_mapS` argument is a callable interpolator or potentially `None` (if interpolator creation failed within `ekf.py`'s `MapCache` logic). The existing code in `get_h`/`get_H` seems to support this already.
    5.  **Consider `crlb` function:** Review the `crlb` function in `ekf.py` (lines 403-537) for similar `isinstance` checks if it also calls `get_h`/`get_H` with interpolators derived from `MapCache`. It appears `crlb` does not have this explicit check, so it might be okay, but worth a quick confirmation.

---

**4. Error: `ERROR tests/test_ekf_online_nn.py - IndexError: index 3 is out of bounds for axis 0 with size 3`**

*   **Persisting Reason:** The `Cnb` matrix shape is likely still `(N,3,3)` from data generation, causing issues when functions expect `(3,3,N)` or a `(3,3)` slice for a time step.
*   **Root Cause Hypothesis:**
    *   The `Cnb` (body-to-navigation DCM) array is created by the placeholder `create_dcm_from_vel` in `create_xyz.py` (line 65) with the shape `(num_samples, 3, 3)`.
    *   This shape is propagated to `Traj` and `INS` objects.
    *   In `rt_comp_main.py`, the `ekf_online_nn` function (line 437) calls `ekf_get_Phi(..., Cnb[:, :, t], ...)`. If `Cnb` is `(N,3,3)`, then `Cnb[:,:,t]` results in an `(N,3)` slice (all samples, 3 columns, for the t-th "page" which is not what's intended).
    *   This incorrectly shaped `(N,3)` slice is passed as the `Cnb` argument to `get_pinson` (via `ekf_get_Phi` -> `model_functions.get_Phi` -> `model_functions.get_pinson`).
    *   Inside `get_pinson` (e.g., `model_functions.py` line 391), the assignment `F[3:6, 11:14] = Cnb` attempts to assign this `(N,3)` matrix into a `(3,3)` block of the `F` matrix. If `N` (the number of time samples, now incorrectly the first dimension of the `Cnb` slice) is not 3, this assignment fails, leading to the `IndexError`. The error "index 3 is out of bounds for axis 0 with size 3" occurs if `N > 3` and the assignment tries to access `Cnb[3,j]` which is out of bounds for the target `(3,3)` block.
*   **Actionable Plan (for Code Mode):**
    1.  **Modify File:** `create_xyz.py`
    2.  **Locate Function:** `create_dcm_from_vel` (placeholder, line 65).
    3.  **Change:** Modify the placeholder `create_dcm_from_vel` to return `Cnb` with the shape `(3, 3, N_samples)`.
        ```python
        # Current placeholder in create_xyz.py:
        # def create_dcm_from_vel(vn: np.ndarray, ve: np.ndarray, dt: float, order: str) -> np.ndarray:
        #     return np.array([np.eye(3)] * len(vn)) # Returns (N, 3, 3)

        # Proposed Change:
        def create_dcm_from_vel(vn: np.ndarray, ve: np.ndarray, dt: float, order: str) -> np.ndarray:
            N_samples = len(vn)
            # Stack identity matrices along the third axis
            return np.stack([np.eye(3)] * N_samples, axis=-1) # Returns (3, 3, N)
        ```
    4.  **Verify `Cnb` Propagation:** Ensure that this `(3,3,N)` shape is consistently maintained when `Cnb` is stored in `Traj` and `INS` objects and accessed in `rt_comp_main.py` and other EKF/MPF files. The slicing `Cnb[:,:,t]` will then correctly yield a `(3,3)` matrix for the t-th time step.
    5.  **Review `Cnb` usage in `get_pinson`:** Confirm that `get_pinson` in `model_functions.py` correctly uses the `(3,3)` `Cnb` matrix for its assignments. The line `F[3:6, 11:14] = Cnb` (line 391) should then work as intended.

---

**5. Error: `ERROR tests/test_map_functions.py - IndexError: tuple index out of range`**

*   **Persisting Reason:** A tuple is being indexed with an out-of-bounds index, most likely when asserting the return value of `map_params`.
*   **Root Cause Hypothesis:**
    *   The most direct location for this error in `tests/test_map_functions.py` is within the `test_map_params` function (lines 157-176). This test calls `map_params` and then indexes its return value up to `[3]` (e.g., `params_s[3]`).
    *   The `map_params` function in `map_utils.py` (lines 137-160) is coded to *always* return a 4-tuple: `(ind0, ind1, int(nx), int(ny))`.
    *   **Contradiction:** If `map_utils.map_params` is indeed the function being called and it behaves as written, it should not cause this error. This suggests one of the following:
        1.  A different `map_params` function (e.g., a misconfigured placeholder or an older version from an unexpected import path) that returns a shorter tuple is being invoked. (Less likely given explicit import).
        2.  There's an extremely subtle condition within `map_utils.map_params` not apparent from the snippet that leads to a shorter tuple (very unlikely given its straightforward return).
        3.  The error occurs elsewhere in `tests/test_map_functions.py` where another tuple is unexpectedly short and indexed. The traceback is crucial here.
        4.  A mocked version of `map_params` is used in the test environment and returns a malformed tuple.
*   **Actionable Plan (for Code Mode):**
    1.  **Request Traceback:** The most important step is to obtain the full traceback for this error to identify the exact line in `tests/test_map_functions.py` causing the `IndexError` and the function that returned the problematic tuple.
    2.  **If `test_map_params` is confirmed as the source:**
        *   **Verify `map_params` Call:** Add debug prints in `tests/test_map_functions.py` just before calling `map_params` to log the types and shapes of `mapS.map`, `mapS.xx`, `mapS.yy`.
        *   **Verify `map_params` Return:** Add a debug print immediately after `params_s = map_params(...)` to log `type(params_s)` and `len(params_s)`.
        *   **Inspect `map_utils.map_params`:** If the inputs seem correct but the length is wrong, re-inspect `map_utils.map_params` (lines 137-160) for any subtle branching logic that might lead to returning a tuple shorter than 4 elements (though none is apparent).
    3.  **If another location is the source (based on traceback):**
        *   Analyze the specific tuple and the indexing operation at that location.
        *   Determine why the tuple is shorter than expected and correct the logic that produces or consumes it.

---

**6. Error: `ERROR tests/test_model_functions.py - TypeError: map_interpolate() got an unexpected keyword argument 'return_vert_deriv'`**

*   **Persisting Reason:** The runtime environment is likely calling a version of `map_interpolate` that does not support the `return_vert_deriv` argument, despite the intended version in `map_utils.py` having it.
*   **Root Cause Hypothesis:**
    *   The `map_interpolate` function defined in `map_utils.py` (lines 205-302) *correctly includes* `return_vert_deriv: bool = False` in its signature.
    *   The test file `tests/test_model_functions.py` explicitly imports `map_interpolate` from `magnavpy.map_utils` (line 18).
    *   The call on line 122, `itp_mapS, der_mapS = map_interpolate(mapS_obj, 'linear', return_vert_deriv=True)`, uses this keyword argument.
    *   The `TypeError` indicates that the `map_interpolate` function actually invoked at runtime does *not* recognize this argument. This strongly suggests:
        1.  **Stale `.pyc` files:** An old compiled version of `map_utils.py` (or a module it depends on that might affect its resolution) without this argument is being used.
        2.  **Import Path/Shadowing Issue:** Python's import mechanism is resolving `map_interpolate` to a different function from another module or an older version, despite the explicit import. This can happen with complex `sys.path` manipulations or if `magnavpy.model_functions` itself (or another imported module) redefines or re-exports `map_interpolate`.
        3.  **Test Environment Patching/Mocking:** The test environment might be inadvertently patching or mocking `map_interpolate` with a version that lacks the argument.
*   **Actionable Plan (for Code Mode):**
    1.  **Verify Called Function:**
        *   The debug prints added in `tests/test_model_functions.py` (lines 120-121) for `map_interpolate.__module__` and `map_interpolate.__qualname__` are critical. Analyze their output.
        *   If they do not point to `magnavpy.map_utils.map_interpolate`, investigate the import path and potential name collisions or incorrect mocking.
    2.  **Clean Python Cache:**
        *   Instruct the user to delete all `__pycache__` directories and `.pyc` files within the `magnavpy` project and any relevant libraries in the environment.
        *   Command (run in project root): `find . -name "__pycache__" -type d -exec rm -r {} +` (Linux/macOS) or equivalent for Windows (e.g., `for /d /r . %d in (__pycache__) do @if exist "%d" rd /s /q "%d"` in cmd).
    3.  **Inspect `sys.path`:** If the issue persists, add `import sys; print(sys.path)` at the beginning of `tests/test_model_functions.py` to understand the Python module search path during test execution.
    4.  **Review `magnavpy.model_functions` Imports:** Double-check if `model_functions.py` itself imports or defines any `map_interpolate` that could conflict, although the test file's direct import should take precedence.

---

**7. Error: `ERROR tests/test_mpf.py - ValueError: setting an array element with a sequence.`**

*   **Persisting Reason:** An assignment within the `mpf` particle update loop is attempting to place an array/sequence into a NumPy array slot that expects a scalar. This is often due to misaligned shapes or an unexpected array result from an intermediate calculation. The `Cnb` shape issue is a strong candidate for causing downstream dimensional errors.
*   **Root Cause Hypothesis:**
    *   The error occurs within the main loop of the `mpf` function in `magnavpy/mpf.py`.
    *   **Primary Suspect (related to Cnb shape):** If the `Cnb` matrix has the incorrect shape `(N,3,3)` instead of `(3,3,N)` (as hypothesized for Error 4), then when `get_Phi` is called (line 189 in `mpf.py`) with `Cnb[:,:,t]`, it receives a malformed `Cnb` slice. This could lead to `get_Phi` (and subsequently `get_pinson`) producing a `Phi` matrix with incorrect dimensions or structure.
    *   When this malformed `Phi` matrix is used to propagate particle states (e.g., `xn_particles_propagated = An_n @ xn_particles + An_l @ xl_particles_temp_for_prop + noise_nl_prop` on line 270, or the linear part update on line 274), the resulting terms might not be purely scalar when assigned to individual elements of `xn_particles` or `xl_particles` if an unexpected broadcasting or element-wise operation occurs due to the faulty `Phi` components (`An_n`, `An_l`, etc.).
    *   **Secondary Possibilities:**
        *   An intermediate calculation within the loop (e.g., related to noise generation, weight calculation, or the Kalman update for linear states) produces an array that is then incorrectly assigned to a scalar slot in `xn_particles`, `xl_particles`, or `x_out`.
        *   One of the input arrays to `mpf` (despite `.astype(float)` on `P0`/`Qd` in tests) might retain an object dtype with array elements that don't get properly handled, leading to a sequence being generated where a float is expected.
*   **Actionable Plan (for Code Mode):**
    1.  **Address `Cnb` Shape First:** Implement the fix for Error 4 (correcting `Cnb` shape to `(3,3,N)` in `create_xyz.py`). This is crucial as it's a likely upstream cause.
    2.  **Request Traceback:** If the error persists after fixing `Cnb` shape, obtain the full traceback for this `ValueError` to pinpoint the exact line in `mpf.py` where the faulty assignment occurs.
    3.  **Inspect Offending Assignment (with traceback):**
        *   Identify the target array and the source value/sequence.
        *   Print the shapes and dtypes of all variables involved in calculating the source value and the target array just before the assignment.
        *   For example, if the error is in `xn_particles_propagated = ...` (line 270) and then `xn_particles = xn_particles_propagated` (line 279), check shapes of `An_n`, `xn_particles`, `An_l`, `xl_particles_temp_for_prop`, `noise_nl_prop`.
    4.  **Ensure Scalar Operations:** If a specific state component is meant to be scalar, ensure all operations contributing to its update result in a scalar before assignment. If an array is produced, ensure correct element extraction (e.g., `result_array[0]`) if appropriate.
    5.  **Check dtypes:** Verify that arrays involved in arithmetic operations, especially those holding particle states, maintain a numeric dtype (e.g., `float64`) and do not inadvertently become `object` arrays.

This comprehensive plan should guide the `code` mode in systematically addressing these persistent errors.